sqlalchemy.exc.OperationalError
sqlalchemy.exc.OperationalError: (sqlite3.OperationalError) no such column: attachment_keywords.description
[SQL: SELECT attachment_keywords.id AS attachment_keywords_id, attachment_keywords.keyword AS attachment_keywords_keyword, attachment_keywords.category AS attachment_keywords_category, attachment_keywords.risk_score AS attachment_keywords_risk_score, attachment_keywords.description AS attachment_keywords_description, attachment_keywords.is_active AS attachment_keywords_is_active 
FROM attachment_keywords 
WHERE attachment_keywords.is_active = 1]
(Background on this error at: https://sqlalche.me/e/20/e3q8)

Traceback (most recent call last)
This is the Copy/Paste friendly version of the traceback.

Traceback (most recent call last):
  File "/Library/Frameworks/Python.framework/Versions/3.13/lib/python3.13/site-packages/sqlalchemy/engine/base.py", line 1963, in _exec_single_context
    self.dialect.do_execute(
    ^
  File "/Library/Frameworks/Python.framework/Versions/3.13/lib/python3.13/site-packages/sqlalchemy/engine/default.py", line 943, in do_execute
    cursor.execute(statement, parameters)
    ~~~~~~~~~~~~~~^^^^^^^^^^^^^^^^^^^^^^^
sqlite3.OperationalError: no such column: attachment_keywords.description

The above exception was the direct cause of the following exception:

Traceback (most recent call last):
  File "/Library/Frameworks/Python.framework/Versions/3.13/lib/python3.13/site-packages/flask/app.py", line 1536, in __call__
    return self.wsgi_app(environ, start_response)
           ~~~~~~~~~~~~~^^^^^^^^^^^^^^^^^^^^^^^^^
  File "/Library/Frameworks/Python.framework/Versions/3.13/lib/python3.13/site-packages/werkzeug/middleware/proxy_fix.py", line 183, in __call__
    return self.app(environ, start_response)
           ~~~~~~~~^^^^^^^^^^^^^^^^^^^^^^^^^
  File "/Library/Frameworks/Python.framework/Versions/3.13/lib/python3.13/site-packages/flask/app.py", line 1514, in wsgi_app
    response = self.handle_exception(e)
  File "/Library/Frameworks/Python.framework/Versions/3.13/lib/python3.13/site-packages/flask/app.py", line 1511, in wsgi_app
    response = self.full_dispatch_request()
  File "/Library/Frameworks/Python.framework/Versions/3.13/lib/python3.13/site-packages/flask/app.py", line 919, in full_dispatch_request
    rv = self.handle_user_exception(e)
  File "/Library/Frameworks/Python.framework/Versions/3.13/lib/python3.13/site-packages/flask/app.py", line 917, in full_dispatch_request
    rv = self.dispatch_request()
  File "/Library/Frameworks/Python.framework/Versions/3.13/lib/python3.13/site-packages/flask/app.py", line 902, in dispatch_request
    return self.ensure_sync(self.view_functions[rule.endpoint])(**view_args)  # type: ignore[no-any-return]
           ~~~~~~~~~~~~~~~~~~~~~~~~~~~~~~~~~~~~~~~~~~~~~~~~~~~~^^^^^^^^^^^^^
  File "/Users/rudolph.vanstaden/Documents/Email_Guardian_New/routes.py", line 474, in admin
    attachment_keywords = AttachmentKeyword.query.filter_by(is_active=True).all()
  File "/Library/Frameworks/Python.framework/Versions/3.13/lib/python3.13/site-packages/sqlalchemy/orm/query.py", line 2704, in all
    return self._iter().all()  # type: ignore
           ~~~~~~~~~~^^
  File "/Library/Frameworks/Python.framework/Versions/3.13/lib/python3.13/site-packages/sqlalchemy/orm/query.py", line 2857, in _iter
    result: Union[ScalarResult[_T], Result[_T]] = self.session.execute(
    
  File "/Library/Frameworks/Python.framework/Versions/3.13/lib/python3.13/site-packages/sqlalchemy/orm/session.py", line 2365, in execute
    return self._execute_internal(
    
  File "/Library/Frameworks/Python.framework/Versions/3.13/lib/python3.13/site-packages/sqlalchemy/orm/session.py", line 2251, in _execute_internal
    result: Result[Any] = compile_state_cls.orm_execute_statement(
    
  File "/Library/Frameworks/Python.framework/Versions/3.13/lib/python3.13/site-packages/sqlalchemy/orm/context.py", line 306, in orm_execute_statement
    result = conn.execute(
    
  File "/Library/Frameworks/Python.framework/Versions/3.13/lib/python3.13/site-packages/sqlalchemy/engine/base.py", line 1415, in execute
    return meth(
    
  File "/Library/Frameworks/Python.framework/Versions/3.13/lib/python3.13/site-packages/sqlalchemy/sql/elements.py", line 523, in _execute_on_connection
    return connection._execute_clauseelement(
    
  File "/Library/Frameworks/Python.framework/Versions/3.13/lib/python3.13/site-packages/sqlalchemy/engine/base.py", line 1637, in _execute_clauseelement
    ret = self._execute_context(
    
  File "/Library/Frameworks/Python.framework/Versions/3.13/lib/python3.13/site-packages/sqlalchemy/engine/base.py", line 1842, in _execute_context
    return self._exec_single_context(
    
  File "/Library/Frameworks/Python.framework/Versions/3.13/lib/python3.13/site-packages/sqlalchemy/engine/base.py", line 1982, in _exec_single_context
    self._handle_dbapi_exception(
    ^
  File "/Library/Frameworks/Python.framework/Versions/3.13/lib/python3.13/site-packages/sqlalchemy/engine/base.py", line 2351, in _handle_dbapi_exception
    raise sqlalchemy_exception.with_traceback(exc_info[2]) from e
  File "/Library/Frameworks/Python.framework/Versions/3.13/lib/python3.13/site-packages/sqlalchemy/engine/base.py", line 1963, in _exec_single_context
    self.dialect.do_execute(
    ^
  File "/Library/Frameworks/Python.framework/Versions/3.13/lib/python3.13/site-packages/sqlalchemy/engine/default.py", line 943, in do_execute
    cursor.execute(statement, parameters)
    ~~~~~~~~~~~~~~^^^^^^^^^^^^^^^^^^^^^^^
sqlalchemy.exc.OperationalError: (sqlite3.OperationalError) no such column: attachment_keywords.description
[SQL: SELECT attachment_keywords.id AS attachment_keywords_id, attachment_keywords.keyword AS attachment_keywords_keyword, attachment_keywords.category AS attachment_keywords_category, attachment_keywords.risk_score AS attachment_keywords_risk_score, attachment_keywords.description AS attachment_keywords_description, attachment_keywords.is_active AS attachment_keywords_is_active 
FROM attachment_keywords 
WHERE attachment_keywords.is_active = 1]
(Background on this error at: https://sqlalche.me/e/20/e3q8)