jinja2.exceptions.UndefinedError
jinja2.exceptions.UndefinedError: 'dict object' has no attribute 'bau_statistics'

Traceback (most recent call last)
This is the Copy/Paste friendly version of the traceback.

Traceback (most recent call last):
  File "C:\Users\Christiaan\AppData\Roaming\Python\Python313\site-packages\flask\app.py", line 1536, in __call__
    return self.wsgi_app(environ, start_response)
           ~~~~~~~~~~~~~^^^^^^^^^^^^^^^^^^^^^^^^^
  File "C:\Users\Christiaan\AppData\Roaming\Python\Python313\site-packages\werkzeug\middleware\proxy_fix.py", line 183, in __call__
    return self.app(environ, start_response)
           ~~~~~~~~^^^^^^^^^^^^^^^^^^^^^^^^^
  File "C:\Users\Christiaan\AppData\Roaming\Python\Python313\site-packages\flask\app.py", line 1514, in wsgi_app
    response = self.handle_exception(e)
  File "C:\Users\Christiaan\AppData\Roaming\Python\Python313\site-packages\flask\app.py", line 1511, in wsgi_app
    response = self.full_dispatch_request()
  File "C:\Users\Christiaan\AppData\Roaming\Python\Python313\site-packages\flask\app.py", line 919, in full_dispatch_request
    rv = self.handle_user_exception(e)
  File "C:\Users\Christiaan\AppData\Roaming\Python\Python313\site-packages\flask\app.py", line 917, in full_dispatch_request
    rv = self.dispatch_request()
  File "C:\Users\Christiaan\AppData\Roaming\Python\Python313\site-packages\flask\app.py", line 902, in dispatch_request
    return self.ensure_sync(self.view_functions[rule.endpoint])(**view_args)  # type: ignore[no-any-return]
           ~~~~~~~~~~~~~~~~~~~~~~~~~~~~~~~~~~~~~~~~~~~~~~~~~~~~^^^^^^^^^^^^^
  File "D:\Email_Guardian_New\routes.py", line 319, in dashboard
    return render_template('dashboard.html',
           ^^^^^^^^^^^^^^^^^^^^^^^^^^^^^^^^^
  File "C:\Users\Christiaan\AppData\Roaming\Python\Python313\site-packages\flask\templating.py", line 150, in render_template
    return _render(app, template, context)
  File "C:\Users\Christiaan\AppData\Roaming\Python\Python313\site-packages\flask\templating.py", line 131, in _render
    rv = template.render(context)
  File "C:\Users\Christiaan\AppData\Roaming\Python\Python313\site-packages\jinja2\environment.py", line 1295, in render
    self.environment.handle_exception()
    ~~~~~~~~~~~~~~~~~~~~~~~~~~~~~~~~~^^
  File "C:\Users\Christiaan\AppData\Roaming\Python\Python313\site-packages\jinja2\environment.py", line 942, in handle_exception
    raise rewrite_traceback_stack(source=source)
  File "D:\Email_Guardian_New\templates\dashboard.html", line 1, in top-level template code
    {% extends "base.html" %}
  File "D:\Email_Guardian_New\templates\base.html", line 150, in top-level template code
    {% block content %}{% endblock %}
    ^^^^^^^^^^^^^^^^^
  File "D:\Email_Guardian_New\templates\dashboard.html", line 326, in block 'content'
    <h4 class="text-primary animated-number" id="bauScore" data-target="{{ "%.1f"|format(bau_analysis.bau_statistics.bau_score or 0) }}">0.0</h4>
    ^
  File "C:\Users\Christiaan\AppData\Roaming\Python\Python313\site-packages\jinja2\environment.py", line 490, in getattr
    return getattr(obj, attribute)
jinja2.exceptions.UndefinedError: 'dict object' has no attribute 'bau_statistics'